Workbook

Sheet food nutritional values
A1: no. | B1: LEGEND | C1: FOOD GROUP | D1: my regrouping | E1: DISH NAME | F1: ENERGY (Kcal) | G1: PROTEIN (g) | H1: CALCIUM (mg) | I1: IRON (mg) | J1: VIT B12 (μg) | K1: CARB (g) | L1: FIBRES (g) | M1: FAT (g) | N1: SUGARS (g) | O1: SODIUM (mg) | P1: CO2eq (g) | Q1: H2O (lt) | R1: N (g)
A2: 84 | B2: Second course dishes | C2: Red meat dishes | D2: Beef | E2: Balsamic braised beef | F2: 236.7 | G2: 17.3 | H2: 5.408 | I2: 1.739 | J2: 1.962 | K2: 0 | L2: 0 | M2: 18.576 | N2: 0 | O2: 53.03 | P2: 2330.58 | Q2: 1420.172 | R2: 24.63616
A3: 96 | B3: Second course dishes | C3: Red meat dishes | D3: Beef | E3: Beef burger | F3: 256.965 | G3: 18.1355 | H3: 12.662 | I3: 1.8899 | J3: 2.0055 | K3: 3.5091 | L3: 0.144 | M3: 18.9654 | N3: 0.2331 | O3: 74.75 | P3: 2342.97 | Q3: 1432.4975 | R3: 25.10212
A4: 88 | B4: Second course dishes | C4: Red meat dishes | D4: Beef | E4: Beef burger with tomato sauce | F4: 266.61 | G4: 17.749 | H4: 14.382 | I4: 2.04778 | J4: 1.9671 | K4: 0.783 | L4: 0.508 | M4: 21.175 | N4: 0.7769 | O4: 98.58 | P4: 2408.02 | Q4: 1447.829 | R4: 25.28264
A5: 99 | B5: Second course dishes | C5: Red meat dishes | D5: Beef | E5: Beef meatloaf | F5: 256.965 | G5: 18.1355 | H5: 12.662 | I5: 1.8899 | J5: 2.0055 | K5: 3.5091 | L5: 0.144 | M5: 18.9654 | N5: 0.2331 | O5: 74.75 | P5: 2342.97 | Q5: 1432.4975 | R5: 25.10212
A6: 100 | B6: Second course dishes | C6: Red meat dishes | D6: Beef | E6: Beef scallops | F6: 151.66 | G6: 21.212 | H6: 8.513 | I6: 2.53652 | J6: 1.0474 | K6: 3.459 | L6: 0.168 | M6: 5.8092 | N6: 0.0874 | O6: 28.6988 | P6: 2343.08 | Q6: 1410.055 | R6: 29.77712
A7: 87 | B7: Second course dishes | C7: Red meat dishes | D7: Beef | E7: Beef scallops with tomato sauce | F7: 261.66 | G7: 18.111 | H7: 11.152 | I7: 1.983 | J7: 1.962 | K7: 4.77 | L7: 0.506 | M7: 18.7028 | N7: 0.4822 | O7: 75.5932 | P7: 2359.7 | Q7: 1436.606 | R7: 25.170864
A8: 91 | B8: Second course dishes | C8: Red meat dishes | D8: Beef | E8: Beef stew with carrots and peppers | F8: 265.908 | G8: 18.3644 | H8: 14.77 | I8: 2.1103 | J8: 1.962 | K8: 2.9548 | L8: 1.766 | M8: 19.763 | N8: 2.19 | O8: 82.05 | P8: 2352.32 | Q8: 1472.5693 | R8: 25.205037
A9: 89 | B9: Second course dishes | C9: Red meat dishes | D9: Beef | E9: Beef stew with potatoes | F9: 347.69 | G9: 20.329 | H9: 36.49 | I9: 3.1605 | J9: 1.962 | K9: 19.55 | L9: 2.91 | M9: 19.968 | N9: 2.448 | O9: 116.164 | P9: 2429.15 | Q9: 1512.5767 | R9: 26.395712
A10: 101 | B10: Second course dishes | C10: Red meat dishes | D10: Beef | E10: Beef strips | F10: 140.4 | G10: 20.81 | H10: 7.145 | I10: 2.477 | J10: 1.044 | K10: 0.513 | L10: 0 | M10: 6.102 | N10: 0 | O10: 28.19 | P10: 2330.58 | Q10: 1420.172 | R10: 29.6344
A11: 93 | B11: Second course dishes | C11: Red meat dishes | D11: Beef | E11: Beef with tomato sauce | F11: 139.65 | G11: 19.1 | H11: 21.36 | I11: 2.1875 | J11: 0 | K11: 0.945 | L11: 0.635 | M11: 6.395 | N11: 0.94 | O11: 141.75 | P11: 2398.85 | Q11: 1447.9375 | R11: 27.22528
A12: 98 | B12: Second course dishes | C12: Red meat dishes | D12: Beef | E12: Beef/pork meatballs with tomato sauce | F12: 244.565 | G12: 19.9965 | H12: 54.452 | I12: 1.8609 | J12: 1.2837 | K12: 4.5501 | L12: 0.702 | M12: 16.1244 | N12: 1.2701 | O12: 137.81 | P12: 1532.34 | Q12: 1077.4288 | R12: 22.087608
A13: 94 | B13: Second course dishes | C13: Red meat dishes | D13: Beef | E13: Boiled beef with tomato sauce | F13: 254.85 | G13: 17.84 | H13: 15.96 | I13: 2.1245 | J13: 1.962 | K13: 0.945 | L13: 0.635 | M13: 19.715 | N13: 0.94 | O13: 109.08 | P13: 2398.85 | Q13: 1447.9375 | R13: 25.43104
A14: 83 | B14: Second course dishes | C14: Red meat dishes | D14: Beef | E14: Roast beef | F14: 146.172 | G14: 20.9356 | H14: 11.815 | I14: 2.5222 | J14: 1.044 | K14: 1.6052 | L14: 0.364 | M14: 6.167 | N14: 0.911 | O14: 34.57 | P14: 2334.72 | Q14: 1424.0473 | R14: 29.819283
A15: 177 | D15: Bread | E15: Bread | F15: 110.4 | G15: 3.284 | H15: 12.44 | I15: 0.5 | J15: 0 | K15: 21.76 | L15: 1.536 | M15: 0.644 | N15: 1.096 | O15: 204.8 | P15: 35.6 | Q15: 41.24 | R15: 1.208512
A16: 125 | B16: Second course dishes | C16: Fish dishes | D16: Breaded fish | E16: Breaded bass fillets | F16: 240.44 | G16: 27.058 | H16: 33.192 | I16: 1.0214 | J16: 5.024 | K16: 9.3846 | L16: 0.384 | M16: 10.6924 | N16: 0.6486 | O16: 121.78 | P16: 474.12 | Q16: 833.79 | R16: 16.95664
A17: 139 | B17: Second course dishes | C17: Fish dishes | D17: Breaded fish | E17: Breaded bass medallions | F17: 198.335 | G17: 24.687 | H17: 15.674 | I17: 0.6311 | J17: 4.82825 | K17: 4.29115 | L17: 0.176 | M17: 9.22885 | N17: 0.28715 | O17: 79.04 | P17: 426.89 | Q17: 792.5015 | R17: 15.37088
A18: 137 | B18: Second course dishes | C18: Fish dishes | D18: Breaded fish | E18: Breaded cod medallions | F18: 147.295 | G18: 21.057 | H18: 14.387 | I18: 0.7411 | J18: 1.51725 | K18: 4.29115 | L18: 0.396 | M18: 5.18085 | N18: 0.28715 | O18: 99.5 | P18: 369.69 | Q18: 380.8815 | R18: 13.10576
A19: 138 | B19: Second course dishes | C19: Fish dishes | D19: Breaded fish | E19: Breaded hake medallions | F19: 152.795 | G19: 20.507 | H19: 37.344 | I19: 1.3021 | J19: 1.16525 | K19: 4.29115 | L19: 0.176 | M19: 6.03885 | N19: 0.28715 | O19: 136.24 | P19: 1174.89 | Q19: 380.8815 | R19: 12.76256
A20: 122 | B20: Second course dishes | C20: Fish dishes | D20: Breaded fish | E20: Breaded sole fillets | F20: 192.92 | G20: 23.648 | H20: 79.282 | I20: 0.9114 | J20: 2.098 | K20: 9.3846 | L20: 0.384 | M20: 6.9524 | N20: 0.6486 | O20: 192.62 | P20: 672.12 | Q20: 203.93 | R20: 14.8288
A21: 140 | B21: Second course dishes | C21: Fish dishes | D21: Breaded fish | E21: Cod balls | F21: 147.295 | G21: 21.057 | H21: 14.387 | I21: 0.7411 | J21: 1.51725 | K21: 4.29115 | L21: 0.396 | M21: 5.18085 | N21: 0.28715 | O21: 99.5 | P21: 369.69 | Q21: 380.8815 | R21: 13.10576
A22: 119 | B22: Second course dishes | C22: Fish dishes | D22: Breaded fish | E22: Cod croquettes | F22: 163.27 | G22: 21.50475 | H22: 15.53 | I22: 0.8086 | J22: 1.51725 | K22: 7.58515 | L22: 0.585 | M22: 5.23395 | N22: 0.3668 | O22: 99.6224 | P22: 372.03 | Q22: 389.202 | R22: 13.270532
A23: 132 | B23: Second course dishes | C23: Fish dishes | D23: Breaded fish | E23: Crispy baked cod sticks | F23: 243.35 | G23: 21.365 | H23: 25.89 | I23: 1.8575 | J23: 1.32 | K23: 24.3 | L23: 2.9 | M23: 5.835 | N23: 1.17 | O23: 66.11 | P23: 360.35 | Q23: 433.4975 | R23: 12.41984
A24: 103 | B24: Second course dishes | C24: Red meat dishes | D24: Breaded meat | E24: Breaded pork cutlets | F24: 219.03 | G24: 20.633 | H24: 29.924 | I24: 1.4336 | J24: 0.534 | K24: 7.0344 | L24: 0.288 | M24: 12.1686 | N24: 0.4824 | O24: 101.75 | P24: 571.86 | Q24: 664.595 | R24: 17.266288
A25: 117 | B25: Second course dishes | C25: White meat dishes | D25: Breaded meat | E25: Breaded chicken breasts | F25: 186.63 | G25: 20.453 | H25: 29.024 | I25: 1.1096 | J25: 0.525 | K25: 7.0344 | L25: 0.288 | M25: 8.7216 | N25: 0.4824 | O25: 123.98 | P25: 388.26 | Q25: 454.085 | R25: 13.654768
A26: 118 | B26: Second course dishes | C26: White meat dishes | D26: Breaded meat | E26: Chicken fingers | F26: 151.9 | G26: 18.418 | H26: 10.924 | I26: 0.755 | J26: 0.351 | K26: 2.928 | L26: 0.168 | M26: 7.4002 | N26: 0.0708 | O26: 73.2088 | P26: 346.36 | Q26: 421.458 | R26: 12.271904
A27: 74 | B27: Second course dishes | C27: Dairy | D27: Cheese | E27: Asiago cheese | F27: 178 | G27: 16.05 | H27: 385 | I27: 0.35 | J27: 0 | K27: 0 | L27: 0 | M27: 12.8 | N27: 0 | O27: 380 | P27: 512 | Q27: 606.95 | R27: 12.5832
... A53: 121 | B53: Second course dishes | C53: Fish dishes | D53: Fish | E53: Sole fillets au gratin | F53: 140.945 | G53: 20.6045 | H53: 57.208 | I53: 0.4155 | J53: 1.837 | K53: 3.501 | L53: 0.144 | M53: 5.0255 | N53: 0.225 | O53: 140.3 | P53: 609.87 | Q53: 150.0815 | R53: 12.757816
A54: 178 | D54: Fruit | E54: Fruit | F54: 89.25 | G54: 1.05 | H54: 21.75 | I54: 0.27 | J54: 0 | K54: 17.4 | L54: 2.955 | M54: 0.39 | N54: 14.835 | O54: 5.175 | P54: 59.549175 | Q54: 143.68213 | R54: 1.5456
A55: 60 | B55: First course dishes | D55: Gnocchi | E55: Gnocchi with Italian meat sauce | F55: 434.91 | G55: 16.82 | H55: 96.468 | I55: 3.661 | J55: 0.8782 | K55: 60.764 | L55: 6.231 | M55: 11.844 | N55: 4.293 | O55: 147.13 | P55: 1027.1 | Q55: 766.84725 | R55: 14.156208
A56: 51 | B56: First course dishes | D56: Gnocchi | E56: Semolina gnocchi | F56: 359.47 | G56: 15.157 | H56: 278.69 | I56: 0.8906 | J56: 1.2268 | K56: 43.429 | L56: 1.685 | M56: 13.336 | N56: 8.032 | O56: 136.66 | P56: 456.58 | Q56: 460.755 | R56: 9.615888
A57: 161 | B57: Side dishes | C57: Vegetables | D57: Gratin vegetables | E57: Fennels au gratin | F57: 96.53 | G57: 2.45 | H57: 78.41 | I57: 0.3675 | J57: 0.0528 | K57: 6.279 | L57: 3.996 | M57: 6.428 | N57: 3.45 | O57: 57.81 | P57: 115.29 | Q57: 124.8205 | R57: 2.843952
A58: 159 | B58: Side dishes | C58: Vegetables | D58: Gratin vegetables | E58: Peppers au gratin | F58: 134.64 | G58: 2.3298 | H58: 20.33 | I58: 0.6525 | J58: 0.00051 | K58: 13.011 | L58: 5.494 | M58: 7.5258 | N58: 7.4634 | O58: 237.67 | P58: 125.54 | Q58: 164.9435 | R58: 2.8719456
A59: 164 | B59: Side dishes | C59: Vegetables | D59: Gratin vegetables | E59: Vegetables au gratin | F59: 83.53 | G59: 2.902 | H59: 52.484 | I59: 0.45178 | J59: 0.0843 | K59: 7.551 | L59: 3.521 | M59: 4.06 | N59: 4.7699 | O59: 40.09 | P59: 141.92 | Q59: 104.52 | R59: 3.28088
A60: 153 | B60: Side dishes | C60: Vegetables | D60: Gratin vegetables | E60: Zucchini au gratin | F60: 84.03 | G60: 2.274 | H60: 32.46 | I60: 0.6265 | J60: 0 | K60: 5.812 | L60: 1.703 | M60: 5.469 | N60: 2.885 | O60: 29.75 | P60: 123.83 | Q60: 126.6015 | R60: 2.901312
A61: 120 | B61: Second course dishes | C61: Fish dishes | D61: Hake | E61: Hake croquettes | F61: 168.77 | G61: 20.95475 | H61: 38.487 | I61: 1.3696 | J61: 1.16525 | K61: 7.58515 | L61: 0.365 | M61: 6.09195 | N61: 0.3668 | O61: 136.3624 | P61: 1177.23 | Q61: 389.202 | R61: 12.927332
A62: 124 | B62: Second course dishes | C62: Fish dishes | D62: Hake | E62: Hake fillets au gratin | F62: 142.925 | G62: 19.8345 | H62: 32.788 | I62: 1.1965 | J62: 1.1 | K62: 3.501 | L62: 0.144 | M62: 5.5755 | N62: 0.225 | O62: 126.66 | P62: 1159.87 | Q62: 368.3215 | R62: 12.277336
A63: 126 | B63: Second course dishes | C63: Fish dishes | D63: Hake | E63: Hake fillets with tomato sauce | F63: 136.01 | G63: 19.915 | H63: 38.388 | I63: 1.487 | J63: 1.1 | K63: 0.945 | L63: 0.635 | M63: 5.621 | N63: 0.94 | O63: 164.66 | P63: 1222.08 | Q63: 377.032 | R63: 12.8976
A64: 82 | B64: Second course dishes | C64: Red meat dishes | D64: Lamb | E64: Lamb stew | F64: 281.7 | G64: 14.69 | H64: 8.981 | I64: 1.208 | J64: 1.368 | K64: 0.828 | L64: 0 | M64: 24.336 | N64: 0.0567 | O64: 67.43 | P64: 2283.78 | Q64: 994.742 | R64: 20.91952
A65: 81 | B65: Second course dishes | C65: Red meat dishes | D65: Lamb | E65: Roast lamb | F65: 447.45 | G65: 17.955 | H65: 30.441 | I65: 2.5755 | J65: 1.368 | K65: 25.128 | L65: 2.7 | M65: 29.601 | N65: 1.2267 | O65: 68.34 | P65: 2336.13 | Q65: 1150.0395 | R65: 22.04496
...

Sheet group lunch lower bounds
A1: GROUP | B1: ENERGY (Kcal) | C1: PROTEIN (g) | D1: CALCIUM (mg) | E1: IRON (mg) | F1: VIT B12 (μg) | G1: CARB (g) | H1: FIBRES (g)
A2: men 19-50 | B2: =('group daily intake requirements'!B2+'group daily intake requirements'!B3)/2*0.3 -> 890.1 | C2: ='group daily intake requirements'!C2*0.3 -> 16.8 | D2: ='group daily intake requirements'!D2*0.3 -> 300 | E2: ='group daily intake requirements'!E2*0.3 -> 2.4 | F2: ='group daily intake requirements'!F2*0.3 -> 0.72 | G2: ='group daily intake requirements'!G2*0.3 -> 39 | H2: ='group daily intake requirements'!H2*0.3 -> 11.4
A3: men 50-70 | B3: ='group daily intake requirements'!B4*0.3 -> 845.1 | C3: ='group daily intake requirements'!C4*0.3 -> 16.8 | D3: ='group daily intake requirements'!D4*0.3 -> 360 | E3: ='group daily intake requirements'!E4*0.3 -> 2.4 | F3: ='group daily intake requirements'!F4*0.3 -> 0.72 | G3: ='group daily intake requirements'!G4*0.3 -> 39 | H3: ='group daily intake requirements'!H4*0.3 -> 9
A4: women (nonpregnant) 19-50 | B4: =('group daily intake requirements'!B6+'group daily intake requirements'!B7)/2*0.3 -> 699.9 | C4: ='group daily intake requirements'!C6*0.3 -> 13.8 | D4: ='group daily intake requirements'!D6*0.3 -> 300 | E4: ='group daily intake requirements'!E6*0.3 -> 5.4 | F4: ='group daily intake requirements'!F6*0.3 -> 0.72 | G4: ='group daily intake requirements'!G6*0.3 -> 39 | H4: ='group daily intake requirements'!H6*0.3 -> 7.5
A5: women (pregnant) 19-50 | B5: =('group daily intake requirements'!B10+'group daily intake requirements'!B11)/2*0.3 -> 809.4 | C5: ='group daily intake requirements'!C10*0.3 -> 21.3 | D5: ='group daily intake requirements'!D10*0.3 -> 300 | E5: ='group daily intake requirements'!E10*0.3 -> 8.1 | F5: ='group daily intake requirements'!F10*0.3 -> 0.78 | G5: ='group daily intake requirements'!G10*0.3 -> 52.5 | H5: ='group daily intake requirements'!H10*0.3 -> 8.4
A6: women 50-70 | B6: ='group daily intake requirements'!B8*0.3 -> 668.4 | C6: ='group daily intake requirements'!C8*0.3 -> 13.8 | D6: ='group daily intake requirements'!D8*0.3 -> 360 | E6: ='group daily intake requirements'!E8*0.3 -> 2.4 | F6: ='group daily intake requirements'!F8*0.3 -> 0.72 | G6: ='group daily intake requirements'!G8*0.3 -> 39 | H6: ='group daily intake requirements'!H8*0.3 -> 6.3

Sheet group daily intake requirements
A1: GROUP | B1: ENERGY (Kcal) | C1: PROTEIN (g) | D1: CALCIUM (mg) | E1: IRON (mg) | F1: VIT B12 (μg) | G1: CARB (g) | H1: FIBRES (g)
A2: men 19-30 | B2: =3067-10*5 -> 3017 | C2: 56 | D2: 1000 | E2: 8 | F2: 2.4 | G2: 130 | H2: 38
A3: men 31-50 | B3: =3067-10*15 -> 2917 | C3: 56 | D3: 1000 | E3: 8 | F3: 2.4 | G3: 130 | H3: 38
A4: men 51-70 | B4: =3067-10*25 -> 2817 | C4: 56 | D4: 1200 | E4: 8 | F4: 2.4 | G4: 130 | H4: 30
A5: men >70 | B5: =3067-10*30 -> 2767 | C5: 56 | D5: 1200 | E5: 8 | F5: 2.4 | G5: 130 | H5: 30
A6: women (nonpregnant) 19-30 | B6: =2403-7*5 -> 2368 | C6: 46 | D6: 1000 | E6: 18 | F6: 2.4 | G6: 130 | H6: 25
A7: women (nonpregnant) 31-50 | B7: =2403-7*15 -> 2298 | C7: 46 | D7: 1000 | E7: 18 | F7: 2.4 | G7: 130 | H7: 25
A8: women (nonpregnant) 51-70 | B8: =2403-7*25 -> 2228 | C8: 46 | D8: 1200 | E8: 8 | F8: 2.4 | G8: 130 | H8: 21
A9: women (nonpregnant) >70 | B9: =2403-7*30 -> 2193 | C9: 46 | D9: 1200 | E9: 8 | F9: 2.4 | G9: 130 | H9: 21
A10: women (pregnant) 19-30 | B10: =(2733+2803)/2-7*5 -> 2733 | C10: 71 | D10: 1000 | E10: 27 | F10: 2.6 | G10: 175 | H10: 28
A11: women (pregnant) 31-50 | B11: =(2733+2803)/2-7*15 -> 2663 | C11: 71 | D11: 1000 | E11: 27 | F11: 2.6 | G11: 175 | H11: 28

Sheet Foglio1 (original)
B1: no. | C1: DISH NAME | D1: ENERGY | E1: FAT | F1: CARB | G1: SUGARS | H1: PROTEIN | I1: FIBRES | J1: SODIUM | K1: CALCIUM | L1: IRON | M1: VIT B12 | N1: CO2eq | O1: H2O | P1: N
D2: (Kcal) | E2: (g) | F2: (g) | G2: (g) | H2: (g) | I2: (g) | J2: (mg) | K2: (mg) | L2: (mg) | M2: (μg) | N2: (g) | O2: (lt) | P2: (g)
B3: 1 | C3: Creamy chickpea pasta | D3: 253.342 | E3: 6.509 | F3: 36.3317 | G3: 2.623 | H3: 10.1571 | I3: 5.516 | J3: 20.234 | K3: 55.718 | L3: 2.5732 | M3: 0 | N3: 90.82 | O3: 239.34525 | P3: 3.1724352
B4: 2 | C4: Creamy bean pasta | D4: 244.642 | E4: 5.099 | F4: 35.9117 | G4: 2.383 | H4: 10.9071 | I4: 6.716 | J4: 19.934 | K4: 52.718 | L4: 3.2932 | M4: 0 | N4: 80.62 | O4: 265.62525 | P4: 3.3524352
B5: 3 | C5: Creamy lentil pasta | D5: 246.142 | E5: 4.919 | F5: 37.5917 | G5: 2.053 | H5: 10.6971 | I5: 5.576 | J5: 20.834 | K5: 30.218 | L5: 3.0532 | M5: 0 | N5: 98.62 | O5: 290.25525 | P5: 3.3020352
B6: 4 | C6: Creamy vegetable pasta (version 1) | D6: 199.43 | E6: 6.57 | F6: 26.721 | G6: 3.947 | H6: 6.652 | I6: 3.227 | J6: 80.408 | K6: 87.538 | L6: 1.242 | M6: 0.132 | N6: 190.68 | O6: 194.75425 | P6: 4.422352
B7: 5 | C7: Creamy vegetable pasta (version 2) | D7: 204.16 | E7: 6.542 | F7: 27.281 | G7: 4.21 | H7: 6.694 | I7: 4.602 | J7: 72.988 | K7: 87.728 | L7: 1.346 | M7: 0.132 | N7: 170.98 | O7: 197.15425 | P7: 4.484176
B8: 6 | C8: Pasta with pesto sauce | D8: 327.7 | E8: 10.103 | F8: 47.71 | G8: 2.284 | H8: 9.035 | I8: 2.725 | J8: 271.44 | K8: 51.85 | L8: 1.1975 | M8: 0 | N8: 152.45 | O8: 158.07 | P8: 4.41232
B9: 7 | C9: Pasta with tomato sauce | D9: 309.902 | E9: 7.063 | F9: 48.2847 | G9: 3.599 | H9: 10.5751 | I9: 3.345 | J9: 131.87 | K9: 83.658 | L9: 1.7062 | M9: 0.132 | N9: 267.42 | O9: 238.51725 | P9: 5.6095072
B10: 8 | C10: Pasta with tomato sauce and basil | D10: 307.54 | E10: 7.028 | F10: 47.857 | G10: 3.273 | H10: 10.531 | I10: 3.166 | J10: 128.14 | K10: 81.488 | L10: 1.693 | M10: 0.132 | N10: 265.58 | O10: 237.06825 | P10: 5.544592
B11: 9 | C11: Pasta with vegan sauce | D11: 314.098 | E11: 7.118 | F11: 49.0678 | G11: 4.212 | H11: 10.6444 | I11: 3.637 | J11: 136.96 | K11: 86.618 | L11: 1.7308 | M11: 0.132 | N11: 270.14 | O11: 240.70425 | P11: 5.7115168
B12: 10 | C12: Pasta with vegetables | D12: 313.202 | E12: 7.115 | F12: 48.6447 | G12: 3.957 | H12: 10.8211 | I12: 3.555 | J12: 133.67 | K12: 87.398 | L12: 1.7782 | M12: 0.132 | N12: 281.42 | O12: 245.23725 | P12: 5.9716192
B13: 11 | C13: Pasta marinara | D13: 285.84 | E13: 5.473 | F13: 47.572 | G13: 2.988 | H13: 8.926 | I13: 3.116 | J13: 96.24 | K13: 31.238 | L13: 1.668 | M13: 0 | N13: 201.78 | O13: 184.617 | P13: 4.251872
B14: 12 | C14: Pasta with tomato sauce and oregano | D14: 285.84 | E14: 5.473 | F14: 47.572 | G14: 2.988 | H14: 8.926 | I14: 3.116 | J14: 96.24 | K14: 31.238 | L14: 1.668 | M14: 0 | N14: 201.78 | O14: 184.617 | P14: 4.251872
... B180: 178 | C180: Fruit | D180: 89.25 | E180: 0.39 | F180: 17.4 | G180: 14.835 | H180: 1.05 | I180: 2.955 | J180: 5.175 | K180: 21.75 | L180: 0.27 | M180: 0 | N180: 59.549175 | O180: 143.68213 | P180: 1.5456
C183: LEGEND
D184: from no. | E184: to no.
C185: First course dishes | D185: 1 | E185: 66
C186: Second course dishes | D186: 67 | E186: 141
C187: Side dishes | D187: 142 | E187: 176
C189: Egg dishes | D189: 67 | E189: 73
C190: Dairy | D190: 74 | E190: 80
C191: Red meat dishes | D191: 81 | E191: 106
C192: White meat dishes | D192: 107 | E192: 118
C193: Fish dishes | D193: 119 | E193: 141
C194: Vegetables | D194: 142 | E194: 169
